2022-11-30 22:07:57,805 - instabot version: 0.117.0 (bot) - INFO - Instabot version: 0.117.0 Started
2022-11-30 22:07:57,806 - instabot version: 0.117.0 (bot) - DEBUG - Bot imported from C:\Users\angel\AppData\Local\Programs\Python\Python310\lib\site-packages\instabot\bot\bot.py
2022-11-30 22:07:57,807 - instabot version: 0.117.0 (api_login) - INFO - Not yet logged in starting: PRE-LOGIN FLOW!
2022-11-30 22:08:00,519 - instabot version: 0.117.0 (api) - WARNING - HTTPSConnectionPool(host='i.instagram.com', port=443): Max retries exceeded with url: /api/v1/accounts/get_prefill_candidates/ (Caused by ProxyError('Cannot connect to proxy.', NewConnectionError('<urllib3.connection.HTTPSConnection object at 0x000001DBE05A9D80>: Failed to establish a new connection: [Errno 11001] getaddrinfo failed')))
2022-11-30 22:08:03,217 - instabot version: 0.117.0 (api) - WARNING - HTTPSConnectionPool(host='i.instagram.com', port=443): Max retries exceeded with url: /api/v1/qe/sync/ (Caused by ProxyError('Cannot connect to proxy.', NewConnectionError('<urllib3.connection.HTTPSConnection object at 0x000001DBE05A9300>: Failed to establish a new connection: [Errno 11001] getaddrinfo failed')))
2022-11-30 22:08:05,923 - instabot version: 0.117.0 (api) - WARNING - HTTPSConnectionPool(host='i.instagram.com', port=443): Max retries exceeded with url: /api/v1/launcher/sync/ (Caused by ProxyError('Cannot connect to proxy.', NewConnectionError('<urllib3.connection.HTTPSConnection object at 0x000001DBE05A9420>: Failed to establish a new connection: [Errno 11001] getaddrinfo failed')))
2022-11-30 22:08:08,622 - instabot version: 0.117.0 (api) - WARNING - HTTPSConnectionPool(host='i.instagram.com', port=443): Max retries exceeded with url: /api/v1/accounts/contact_point_prefill/ (Caused by ProxyError('Cannot connect to proxy.', NewConnectionError('<urllib3.connection.HTTPSConnection object at 0x000001DBE05AA170>: Failed to establish a new connection: [Errno 11001] getaddrinfo failed')))
